异常
#Throwabel:最底层接口
#Error
    一般是指java虚拟机相关的问题，系统崩溃、虚拟机出错误、动态链接失败等，
    这种错误无法恢复或不可能捕获，将导致应用程序中断，通常应用程序无法处理这些错误
#Exception
    运行时异常--子类继承RuntimeException
    非运行时异常--子类继承Exception


#运行时异常
    1.NullPointerException、IndexOutOfBoundsException
    2.抛出该异常时可以不用try catch捕捉处理，只要执行到throw，运行异常抛出，如果没有捕获处理这个异常，系统会把异常自动向上抛出到最上层
    3.如果是普通线程就由Thread.run()抛出，如果是主线程就被main()抛出。
    4.抛出之后，如果是线程，这个线程也就退出了。如果是主程序抛出的异常，那么这整个程序也就退出了
    5.jvm会自动打印出来，throw new后面的程序不会执行（finally会执行）
#非运行时异常
    1.IOException、FileNotFoundExcetion 、SQLException
    2.需要try catch捕捉或向上声明抛出异常，交给调用他的方法处理
    3.手动在catch中处理，可打印出异常，或抛出包裹此异常的异常(多层try catch)


#异常的两个过程
    抛出异常
        throw 
        throws
        系统自动抛出
    捕捉异常

#好的编程习惯：
    1.在写程序时，对可能会出现异常的部分通常要用try{...}catch{...}去捕捉它并对它进行处理；
    2.用try{...}catch{...}捕捉了异常之后一定要对在catch{...}中对其进行处理，那怕是最简单的一句输出语句，或栈输入e.printStackTrace();
    3.如果是捕捉IO输入输出流中的异常，一定要在try{...}catch{...}后加finally{...}把输入输出流关闭；
    4.如果在函数体内用throw抛出了某种异常，最好要在函数名中加throws抛异常声明，然后交给调用它的上层函数进行处理。

#抛出多层异常的日志
    异常从外向里由上而下显示
    TestException1: 222
    at Test2.test(Test2.java:9)
    at FileClientTest.main(FileClientTest.java:89)
    Caused by: TestException1: ooooooooo
    at Test.test(Test.java:8)
    at Test2.test(Test2.java:7)
    ... 1 more

#finally中的语句总会执行
#异常时线程调用的方法集合
    Throwable中属性stacktraceElemet[]数组
    此数组调用本地方法native getstacktrace()从jvm栈信息中获取
